<robot name="my_robot">
    <link name="base_link">
        <visual>
            <geometry>
                <box size="0.5 0.3 0.2"/>
            </geometry>
            <material name="blue">
                <color rgba="0.0 0.0 1.0 1.0"/>
            </material>
        </visual>
    </link>

    <!-- Ruote -->
    <link name="left_wheel"/>
    <joint name="left_wheel_joint" type="continuous">
        <parent link="base_link"/>
        <child link="left_wheel"/>
        <origin xyz="-0.15 0 0"/>
        <axis xyz="0 1 0"/>
    </joint>

    <link name="right_wheel"/>
    <joint name="right_wheel_joint" type="continuous">
        <parent link="base_link"/>
        <child link="right_wheel"/>
        <origin xyz="0.15 0 0"/>
        <axis xyz="0 1 0"/>
    </joint>
</robot>
